Workbook

Sheet Data
A1: תדירות/גיליון | B1: אינדיקטור | C1: שם | D1: יחידות | E1: מקור | F1: קישור | G1: הערות | H1: דיליי בפרסום
A2: Daily | B2: רכישות בכרטיסי אשראי | D2: ממוצע 7 ימים, מנוכה עונתיות | E2: בנק ישראל | G2: באתר קיים רק מ-2016, צריך לבקש מהם את הסדרות, איש קשר - שי צור | H2: כ-3 ימים
A3: Daily | B3: גוגל טרנדס | D3: אינדקס | E3: גוגל | G3: מיוצר על ידי קוד נפרד, נתונים רק מ-2004 | H3: אין
A6: Monthly | B6: פדיון רשתות שיווק | C6: Rev_trade | D6: מנוכה עונתיות, מחירי 2011 | E6: הלמס | F6: rdata | H6: 30 יום
A7: Monthly | B7: פדיון כל ענפי הכלכלה | C7: Rev | D7: מנוכה עונתיות, מחירי 2011 | E7: הלמס | F7: rdata | H7: 50 יום
A8: Monthly | B8: סה"כ מע"מ נטו | C8: VAT | D8: נתונים שוטפים | E8: משרד האוצר | F8: taxes | H8: אין
A9: Monthly | B9: מדד אמון הצרכנים | C9: cons_trust | D9: אינדקס | E9: בנק הפועלים | F9: rdata | H9: 8 יום
A12: Quarterly | B12: הוצאה לצריכה פרטית | C12: Private_consumption | D12: מנוכה עונתיות | E12: הלמס | F12: Arkadi | H12: 50 יום
A13: Quarterly | B13: ריבית בנק ישראל | C13: Intrest_rate | D13: בנקודות אחוז | E13: בנק ישראל | F13: GPMN | G13: לקחת מ-GPMN אגרגציה רבעונית לפי נתונים יומיים | H13: אין

Sheet Monthly
A1: Type | E1: CBS | F1: TAX | G1: TAX | H1: TAX | I1: CBS | J1: CBS | K1: BOI | L1: BOI | M1: BOI | N1: BOI | O1: BOI | P1: BOI | Q1: BOI | R1: BOI | S1: TAX | T1: TAX | U1: TAX | V1: TAX | W1: TAX | X1: TAX | Y1: TAX | Z1: TAX | AA1: TAX | AB1: TAX | AC1: CBS | AD1: CBS | AE1: CBS | AF1: CBS | AG1: CBS | AH1: BOI | AI1: CBS | AJ1: CBS | AK1: CBS | AL1: CBS | AM1: CBS
A2: Source | E2: Real | F2: Nominal | G2: Nominal | H2: Nominal | I2: Nominal | J2: SA | K2: SA | L2: Nominal | M2: Real | N2: Nominal | O2: Nominal | P2: Nominal | Q2: Nominal | R2: Nominal | S2: Nominal | T2: Nominal | U2: Nominal | V2: Nominal | W2: Nominal | X2: Nominal | Y2: Nominal | Z2: Nominal | AA2: Nominal | AB2: Nominal | AC2: SA | AD2: SA | AE2: SA | AF2: SA | AG2: SA | AJ2: SA | AK2: SA | AM2: SA
A3: Release Lag | E3: 15 | F3: 0 | G3: 0 | H3: 0 | I3: 16 | J3: 12 | S3: 0 | T3: 0 | U3: 0 | V3: 0 | W3: 0 | X3: 0 | Y3: 0 | Z3: 0 | AA3: 0 | AB3: 0 | AC3: 16 | AD3: 16 | AE3: 18 | AF3: 94 | AG3: 94
A4: Date | B4: Month | C4: Quarter | D4: Year | E4: CPI | F4: dir | G4: indir | H4: VAT | I4: imp | J4: cons_trust | K4: real_credit_card | L4: Oil | M4: Reer | N4: Dollar | O4: TA35 | P4: TA125 | Q4: Nasdaq | R4: sp500 | S4: VAT_rate | T4: rev | U4: rev_trade | V4: rev_trade2 | W4: rev_food | X4: סה"כ אגף מס הכנסה נטו | Y4: ניכויים ושוק ההון | Z4: סה"כ מיסי יבוא | AA4: סה"כ מיסים מקומיים | AB4: סה"כ מסים עקיפים | AC4: שיעור אבטלה (גילאי 25-64, בנקודות אחוז) | AD4: שיעור השתתפות (גילאי 25-64, בנקודות אחוז) | AE4: שיעור תעסוקה (גילאי 25-64) | AF4: שכר ריאלי | AG4: משרות שכיר | AH4: יתרות מט"ח במליוני דולרים | AI4: מדד מחירי דירות (1993=100) - אמצע התקופה הנסקרת | AJ4: מדדי ערך רכישות בכרטיסי אשראי (סה"כ) (2002=100) | AK4: מדד הייצור התעשייתי (סה"כ) | AL4: המדד המשולב למצב המשק | AM4: דירות שנמכרו בקצב שנתי
A5: 34700 | B5: =MONTH(A5) -> 1 | C5: =ROUNDUP(B5/3,0) -> 1 | D5: =YEAR(A5) -> 1995 | E5: 50.644059 | L5: 18.039524 | N5: 3.0117143 | O5: 165.50652 | P5: 163.97826 | Q5: 758.01238 | R5: 465.25 | S5: 0.17 | AH5: 7655.8463 | AI5: 140.3
A6: 34731 | B6: =MONTH(A6) -> 2 | C6: =ROUNDUP(B6/3,0) -> 1 | D6: =YEAR(A6) -> 1995 | E6: 50.728537 | L6: 18.57 | M6: 93.34 | N6: 3.00955 | O6: 160.887 | P6: 161.739 | Q6: 784.24368 | R6: 481.92474 | S6: 0.17 | AH6: 8618.6176 | AI6: 140.7
A7: 34759 | B7: =MONTH(A7) -> 3 | C7: =ROUNDUP(B7/3,0) -> 1 | D7: =YEAR(A7) -> 1995 | E7: 50.686298 | L7: 18.53913 | M7: 92.47 | N7: 2.9761429 | O7: 160.5081 | P7: 159.40048 | Q7: 807.16217 | R7: 493.15304 | S7: 0.17 | AH7: 9091.1186 | AI7: 141.5
A8: 34790 | B8: =MONTH(A8) -> 4 | C8: =ROUNDUP(B8/3,0) -> 2 | D8: =YEAR(A8) -> 1995 | E8: 51.150922 | L8: 19.896316 | M8: 90.55 | N8: 2.9589412 | O8: 166.3595 | P8: 164.7245 | Q8: 825.33842 | R8: 507.90579 | S8: 0.17 | AH8: 9656.7218 | AI8: 142.7
A9: 34820 | B9: =MONTH(A9) -> 5 | C9: =ROUNDUP(B9/3,0) -> 2 | D9: =YEAR(A9) -> 1995 | E9: 51.657785 | L9: 19.741818 | M9: 90 | N9: 3.0042381 | O9: 180.16381 | P9: 176.9481 | Q9: 859.77045 | R9: 523.81364 | S9: 0.17 | AH9: 9759.9675 | AI9: 144.4
A10: 34851 | B10: =MONTH(A10) -> 6 | C10: =ROUNDUP(B10/3,0) -> 2 | D10: =YEAR(A10) -> 1995 | E10: 51.82674 | L10: 18.445909 | M10: 90.01 | N10: 2.981 | O10: 190.041 | P10: 188.3285 | Q10: 906.03545 | R10: 539.35409 | S10: 0.17 | AH10: 8931.5008 | AI10: 145.5
A11: 34881 | B11: =MONTH(A11) -> 7 | C11: =ROUNDUP(B11/3,0) -> 3 | D11: =YEAR(A11) -> 1995 | E11: 51.953455 | L11: 17.3255 | M11: 90.34 | N11: 2.9552857 | O11: 191.66227 | P11: 189.12182 | Q11: 979.364 | R11: 557.3665 | S11: 0.17 | AH11: 9076.1771 | AI11: 148.7
A12: 34912 | B12: =MONTH(A12) -> 8 | C12: =ROUNDUP(B12/3,0) -> 3 | D12: =YEAR(A12) -> 1995 | E12: 52.587034 | L12: 18.02087 | M12: 91.14 | N12: 3.0307826 | O12: 203.87955 | P12: 201.32591 | Q12: 1009.5861 | R12: 559.11 | S12: 0.17 | AH12: 8273.9323 | AI12: 151.8
A13: 34943 | B13: =MONTH(A13) -> 9 | C13: =ROUNDUP(B13/3,0) -> 3 | D13: =YEAR(A13) -> 1995 | E13: 53.093897 | L13: 18.2255 | M13: 91.74 | N13: 3.0355789 | O13: 209.76765 | P13: 206.19412 | Q13: 1051 | R13: 578.7655 | S13: 0.17 | AH13: 8989.8373 | AI13: 151.9
A14: 34973 | B14: =MONTH(A14) -> 10 | C14: =ROUNDUP(B14/3,0) -> 4 | D14: =YEAR(A14) -> 1995 | E14: 53.642999 | L14: 17.433182 | M14: 93.07 | N14: 3.0102778 | O14: 198.53706 | P14: 194.45412 | Q14: 1022.1482 | R14: 582.91818 | S14: 0.17 | AH14: 8529.6768 | AI14: 153.5
A15: 35004 | B15: =MONTH(A15) -> 11 | C15: =ROUNDUP(B15/3,0) -> 4 | D15: =YEAR(A15) -> 1995 | E15: 54.023146 | L15: 17.9925 | M15: 93.45 | N15: 3.042 | O15: 195.405 | P15: 189.73864 | Q15: 1046.6367 | R15: 595.53238 | S15: 0.17 | AH15: 8409.2189 | AI15: 157.9
A16: 35034 | B16: =MONTH(A16) -> 12 | C16: =ROUNDUP(B16/3,0) -> 4 | D16: =YEAR(A16) -> 1995 | E16: 54.656725 | L16: 19.0265 | M16: 93.23 | N16: 3.1197368 | O16: 210.60381 | P16: 203.42048 | Q16: 1047.035 | R16: 614.571 | S16: 0.17 | AH16: 8307.3915 | AI16: 162.7
A17: 35065 | B17: =MONTH(A17) -> 1 | C17: =ROUNDUP(B17/3,0) -> 1 | D17: =YEAR(A17) -> 1996 | E17: 55.121349 | F17: 3615.7 | G17: 3420.2 | H17: 2420 | I17: 703 | L17: 18.854545 | M17: 92.65 | N17: 3.1295455 | O17: 218.74565 | P17: 210.57174 | Q17: 1024.9455 | R17: 614.42 | S17: 0.17 | X17: =[1]ישיר!D6/1000 -> 4094.236 | Y17: 2775.426 | Z17: =[1]עקיף!H6 -> 703 | AA17: =[1]עקיף!P6 -> 465 | AB17: =[1]עקיף!Q6 -> 3588 | AH17: 9177.2917 | AI17: 164.7
A18: 35096 | B18: =MONTH(A18) -> 2 | C18: =ROUNDUP(B18/3,0) -> 1 | D18: =YEAR(A18) -> 1996 | E18: 55.628212 | F18: 4442.9 | G18: 3114 | H18: 1999 | I18: 637 | L18: 19.0935 | M18: 93.56 | N18: 3.1131429 | O18: 215.54048 | P18: 206.9281 | Q18: 1094.0165 | R18: 649.542 | S18: 0.17 | X18: =[1]ישיר!D7/1000 -> 4438.306 | Y18: 2717.37 | Z18: =[1]עקיף!H7 -> 637 | AA18: =[1]עקיף!P7 -> 450 | AB18: =[1]עקיף!Q7 -> 3086 | AH18: 10024.64 | AI18: 164.7
A19: 35125 | B19: =MONTH(A19) -> 3 | C19: =ROUNDUP(B19/3,0) -> 1 | D19: =YEAR(A19) -> 1996 | E19: 56.177314 | F19: 4408.6 | G19: 3707.4 | H19: 2465 | I19: 726 | L19: 21.332381 | M19: 94.75 | N19: 3.0991053 | O19: 210.082 | P19: 200.4405 | Q19: 1092.6471 | R19: 647.07476 | S19: 0.17 | X19: =[1]ישיר!D8/1000 -> 4409.521 | Y19: 2903.474 | Z19: =[1]עקיף!H8 -> 726 | AA19: =[1]עקיף!P8 -> 481 | AB19: =[1]עקיף!Q8 -> 3672 | AH19: 9836.6582 | AI19: 167
A20: 35156 | B20: =MONTH(A20) -> 4 | C20: =ROUNDUP(B20/3,0) -> 2 | D20: =YEAR(A20) -> 1996 | E20: 57.106562 | F20: 4051.2 | G20: 3154.1 | H20: 2331 | I20: 605 | L20: 23.497143 | M20: 95.95 | N20: 3.164875 | O20: 205.92688 | P20: 195.68 | Q20: 1135.6281 | R20: 647.17286 | S20: 0.17 | X20: =[1]ישיר!D9/1000 -> 4015.955 | Y20: 2703.784 | Z20: =[1]עקיף!H9 -> 605 | AA20: =[1]עקיף!P9 -> 437 | AB20: =[1]עקיף!Q9 -> 3373 | AH20: 9589.8175 | AI20: 171.8
A21: 35186 | B21: =MONTH(A21) -> 5 | C21: =ROUNDUP(B21/3,0) -> 2 | D21: =YEAR(A21) -> 1996 | E21: 58.07805 | F21: 4320.3 | G21: 3605.4 | H21: 2380 | I21: 715 | L21: 21.165455 | M21: 95.81 | N21: 3.25275 | O21: 215.144 | P21: 203.9375 | Q21: 1220.5405 | R21: 661.23045 | S21: 0.17 | X21: =[1]ישיר!D10/1000 -> 4388.474 | Y21: 2.9243 | Z21: =[1]עקיף!H10 -> 715 | AA21: =[1]עקיף!P10 -> 542 | AB21: =[1]עקיף!Q10 -> 3637 | AH21: 9373.0643 | AI21: 175.3
A22: 35217 | B22: =MONTH(A22) -> 6 | C22: =ROUNDUP(B22/3,0) -> 2 | D22: =YEAR(A22) -> 1996 | E22: 58.500436 | F22: 4207.7 | G22: 3213.1 | H22: 2114.5 | I22: 704.2 | L22: 20.4235 | M22: 95.23 | N22: 3.2555 | O22: 214.71381 | P22: 203.20143 | Q22: 1205.0755 | R22: 668.499 | S22: 0.17 | X22: =[1]ישיר!D11/1000 -> 3910.048 | Y22: 2543.934 | Z22: =[1]עקיף!H11 -> 704.2 | AA22: =[1]עקיף!P11 -> 458 | AB22: =[1]עקיף!Q11 -> 3276.7 | AH22: 9007.1596 | AI22: 174.6
A23: 35247 | B23: =MONTH(A23) -> 7 | C23: =ROUNDUP(B23/3,0) -> 3 | D23: =YEAR(A23) -> 1996 | E23: 58.66939 | F23: 4586.8 | G23: 3898.4 | H23: 2742.1 | I23: 603.2 | L23: 21.302273 | M23: 95.69 | N23: 3.1794762 | O23: 193.38714 | P23: 182.44333 | Q23: 1105.6127 | R23: 644.07045 | S23: 0.17 | X23: =[1]ישיר!D12/1000 -> 4803.693 | Y23: 3308.043 | Z23: =[1]עקיף!H12 -> 603.2 | AA23: =[1]עקיף!P12 -> 588.9 | AB23: =[1]עקיף!Q12 -> 3934.2 | AH23: 9052.0327 | AI23: 171.6
A24: 35278 | B24: =MONTH(A24) -> 8 | C24: =ROUNDUP(B24/3,0) -> 3 | D24: =YEAR(A24) -> 1996 | E24: 58.880583 | F24: 4064.2 | G24: 3144 | H24: 2052.1 | I24: 614.71 | L24: 21.903182 | M24: 97.73 | N24: 3.1461364 | O24: 187.31048 | P24: 176.91 | Q24: 1134.2459 | R24: 662.68227 | S24: 0.17 | X24: =[1]ישיר!D13/1000 -> 4111.349 | Y24: 2987.938 | Z24: =[1]עקיף!H13 -> 614.71 | AA24: =[1]עקיף!P13 -> 531.5 | AB24: =[1]עקיף!Q13 -> 3198.31 | AH24: 9655.0439 | AI24: 170.8
A25: 35309 | B25: =MONTH(A25) -> 9 | C25: =ROUNDUP(B25/3,0) -> 3 | D25: =YEAR(A25) -> 1996 | E25: 59.134014 | F25: 4635.4 | G25: 3911.4 | H25: 2669.6 | I25: 621.95 | L25: 23.9715 | M25: 98.46 | N25: 3.1668947 | O25: 199.20684 | P25: 189.71421 | Q25: 1186.442 | R25: 674.8855 | S25: 0.17 | X25: =[1]ישיר!D14/1000 -> 4618.324 | Y25: 3198.959 | Z25: =[1]עקיף!H14 -> 621.95 | AA25: =[1]עקיף!P14 -> 540.7 | AB25: =[1]עקיף!Q14 -> 3832.25 | AH25: 10367.67 | AI25: 173.5
A26: 35339 | B26: =MONTH(A26) -> 10 | C26: =ROUNDUP(B26/3,0) -> 4 | D26: =YEAR(A26) -> 1996 | E26: 59.598639 | F26: 3910.4 | G26: 3438.5 | H26: 2183.5 | I26: 712.98 | L26: 24.87913 | M26: 98.48 | N26: 3.2253478 | O26: 195.83609 | P26: 185.80522 | Q26: 1234.0422 | R26: 701.45565 | S26: 0.17 | X26: =[1]ישיר!D15/1000 -> 3945.093 | Y26: 2735.434 | Z26: =[1]עקיף!H15 -> 712.98 | AA26: =[1]עקיף!P15 -> 564 | AB26: =[1]עקיף!Q15 -> 3460.48 | AH26: 11819.772 | AI26: 176.4
A27: 35370 | B27: =MONTH(A27) -> 11 | C27: =ROUNDUP(B27/3,0) -> 4 | D27: =YEAR(A27) -> 1996 | E27: 59.978786 | F27: 4498.2 | G27: 3484.4 | H27: 2424.9 | I27: 611.325 | L27: 23.705 | M27: 97.67 | N27: 3.244381 | O27: 203.3855 | P27: 193.694 | Q27: 1259.831 | R27: 735.669 | S27: 0.17 | X27: =[1]ישיר!D16/1000 -> 4513.833 | Y27: 3072.494 | Z27: =[1]עקיף!H16 -> 611.325 | AA27: =[1]עקיף!P16 -> 460.5 | AB27: =[1]עקיף!Q16 -> 3496.725 | AH27: 11409.308 | AI27: 177.1
A28: 35400 | B28: =MONTH(A28) -> 12 | C28: =ROUNDUP(B28/3,0) -> 4 | D28: =YEAR(A28) -> 1996 | E28: 60.44341 | F28: 4054.2 | G28: 4160.322 | H28: 2089.8 | I28: 759.798 | L28: 25.228571 | M28: 96.83 | N28: 3.2764737 | O28: 215.16409 | P28: 206.18636 | Q28: 1292.151 | R28: 743.24905 | S28: 0.17 | X28: =[1]ישיר!D17/1000 -> 3749.646 | Y28: 2833.59 | Z28: =[1]עקיף!H17 -> 759.798 | AA28: =[1]עקיף!P17 -> 847 | AB28: =[1]עקיף!Q17 -> 3696.598 | AH28: 11574.64 | AI28: 178.4
... A40: 35765 | B40: =MONTH(A40) -> 12 | C40: =ROUNDUP(B40/3,0) -> 4 | D40: =YEAR(A40) -> 1997 | E40: 64.667268 | F40: 4810.4 | G40: 4274.033 | H40: 2345.324 | I40: 914.392 | L40: 18.332727 | M40: 101.16 | N40: 3.5343889 | O40: 295.9645 | P40: 283.75 | Q40: 1566.9968 | R40: 962.36545 | S40: 0.17 | X40: =[1]ישיר!D29/1000 -> 4249.34 | Y40: 3199.78 | Z40: =[1]עקיף!H29 -> 914.392 | AA40: =[1]עקיף!P29 -> 676 | AB40: =[1]עקיף!Q29 -> 3935.716 | AH40: 20332.481 | AI40: 190.9
A41: 35796 | B41: =MONTH(A41) -> 1 | C41: =ROUNDUP(B41/3,0) -> 1 | D41: =YEAR(A41) -> 1998 | E41: 64.878461 | F41: 5156.8 | G41: 3681 | H41: 2646.3 | I41: 536.1 | L41: 16.724 | M41: 103.3 | N41: 3.5771905 | O41: 284.03571 | P41: 273.95619 | Q41: 1570.2345 | R41: 963.359 | S41: 0.17 | X41: =[1]ישיר!D30/1000 -> 5869.41 | Y41: 4105.199 | Z41: =[1]עקיף!H30 -> 536.1 | AA41: =[1]עקיף!P30 -> 592.8 | AB41: =[1]עקיף!Q30 -> 3775.2 | AH41: 21923.216 | AI41: 191.1 | AL41: 39.363458 | AM41: 19212
A42: 35827 | B42: =MONTH(A42) -> 2 | C42: =ROUNDUP(B42/3,0) -> 1 | D42: =YEAR(A42) -> 1998 | E42: 64.836223 | F42: 4392.1 | G42: 3690.2 | H42: 2440.4 | I42: 573.4 | L42: 16.06 | M42: 104.14 | N42: 3.5943 | O42: 281.8825 | P42: 271.0345 | Q42: 1714.8721 | R42: 1023.7421 | S42: 0.17 | X42: =[1]ישיר!D31/1000 -> 3785.349 | Y42: 2612.299 | Z42: =[1]עקיף!H31 -> 573.4 | AA42: =[1]עקיף!P31 -> 537.9 | AB42: =[1]עקיף!Q31 -> 3551.7 | AH42: 21811.626 | AI42: 190.1 | AL42: 39.473875 | AM42: 21600
A43: 35855 | B43: =MONTH(A43) -> 3 | C43: =ROUNDUP(B43/3,0) -> 1 | D43: =YEAR(A43) -> 1998 | E43: 64.709507 | F43: 6098.3 | G43: 4582 | H43: 3239.5 | I43: 818.4 | L43: 15.115455 | M43: 102.61 | N43: 3.58625 | O43: 306.43591 | P43: 294.80318 | Q43: 1781.2695 | R43: 1076.8277 | S43: 0.17 | X43: =[1]ישיר!D32/1000 -> 6746 | Y43: 4603.479 | Z43: =[1]עקיף!H32 -> 818.4 | AA43: =[1]עקיף!P32 -> 657.5 | AB43: =[1]עקיף!Q32 -> 4715.4 | AH43: 21603.442 | AI43: 191.6 | AL43: 39.615054 | AM43: 20196
A44: 35886 | B44: =MONTH(A44) -> 4 | C44: =ROUNDUP(B44/3,0) -> 2 | D44: =YEAR(A44) -> 1998 | E44: 65.596517 | F44: 5439.5 | G44: 3588 | H44: 2329.5 | I44: 762.6 | L44: 15.35381 | M44: 102.43 | N44: 3.7050556 | O44: 327.08474 | P44: 311.05684 | Q44: 1852.3 | R44: 1112.1962 | S44: 0.17 | X44: =[1]ישיר!D33/1000 -> 5446.3 | Y44: 3585.355 | Z44: =[1]עקיף!H33 -> 762.6 | AA44: =[1]עקיף!P33 -> 575.1 | AB44: =[1]עקיף!Q33 -> 3667.2 | AH44: 21837.742 | AI44: 193.5 | AL44: 39.684279 | AM44: 18012
A45: 35916 | B45: =MONTH(A45) -> 5 | C45: =ROUNDUP(B45/3,0) -> 2 | D45: =YEAR(A45) -> 1998 | E45: 65.849949 | F45: 5579.4 | G45: 4057.6 | H45: 2923.2 | I45: 597.7 | L45: 14.914 | M45: 100 | N45: 3.6654737 | O45: 339.001 | P45: 323.0095 | Q45: 1836.3925 | R45: 1108.417 | S45: 0.17 | X45: =[1]ישיר!D34/1000 -> 5624.066 | Y45: 3818.548 | Z45: =[1]עקיף!H34 -> 597.7 | AA45: =[1]עקיף!P34 -> 637.9 | AB45: =[1]עקיף!Q34 -> 4158.8 | AH45: 21537.104 | AI45: 193.4 | AL45: 39.734629 | AM45: 18888
A46: 35947 | B46: =MONTH(A46) -> 6 | C46: =ROUNDUP(B46/3,0) -> 2 | D46: =YEAR(A46) -> 1998 | E46: 66.10338 | F46: 4858.1 | G46: 3844.4 | H46: 2381.7 | I46: 817.3 | L46: 13.721818 | M46: 101.03 | N46: 3.6642273 | O46: 340.04773 | P46: 325.01273 | Q46: 1795.7445 | R46: 1108.3895 | S46: 0.17 | X46: =[1]ישיר!D35/1000 -> 4699.947 | Y46: 3259.932 | Z46: =[1]עקיף!H35 -> 817.3 | AA46: =[1]עקיף!P35 -> 675.3 | AB46: =[1]עקיף!Q35 -> 3874.3 | AH46: 21322.432 | AI46: 190.1 | AL46: 39.845791 | AM46: 17256
A47: 35977 | B47: =MONTH(A47) -> 7 | C47: =ROUNDUP(B47/3,0) -> 3 | D47: =YEAR(A47) -> 1998 | E47: 66.018903 | F47: 6146.2 | G47: 4327 | H47: 3041.95 | I47: 612.8 | L47: 14.172727 | M47: 102.33 | N47: 3.6600435 | O47: 330.41864 | P47: 316.77455 | Q47: 1941.5768 | R47: 1156.5773 | S47: 0.17 | X47: =[1]ישיר!D36/1000 -> 6148.992 | Y47: 4110.934 | Z47: =[1]עקיף!H36 -> 612.8 | AA47: =[1]עקיף!P36 -> 699.9 | AB47: =[1]עקיף!Q36 -> 4354.65 | AH47: 21405.084 | AI47: 188.1 | AL47: 39.930907 | AM47: 18168
A48: 36008 | B48: =MONTH(A48) -> 8 | C48: =ROUNDUP(B48/3,0) -> 3 | D48: =YEAR(A48) -> 1998 | E48: 66.356812 | F48: 5463.8 | G48: 4029.5 | H48: 2546.2 | I48: 775.9 | L48: 13.471905 | M48: 102.57 | N48: 3.7075714 | O48: 323.73095 | P48: 312.29714 | Q48: 1784.7505 | R48: 1074.6205 | S48: 0.17 | X48: =[1]ישיר!D37/1000 -> 4776.638 | Y48: 3009.388 | Z48: =[1]עקיף!H37 -> 775.9 | AA48: =[1]עקיף!P37 -> 687.4 | AB48: =[1]עקיף!Q37 -> 4009.5 | AH48: 21544.499 | AI48: 191 | AL48: 40.048978 | AM48: 24612
A49: 36039 | B49: =MONTH(A49) -> 9 | C49: =ROUNDUP(B49/3,0) -> 3 | D49: =YEAR(A49) -> 1998 | E49: 67.28606 | F49: 5758.9 | G49: 4508.7 | H49: 3407 | I49: 696.4 | L49: 15.031429 | M49: 102.05 | N49: 3.8448889 | O49: 294.78294 | P49: 288.81353 | Q49: 1663.4271 | R49: 1020.64 | S49: 0.17 | X49: =[1]ישיר!D38/1000 -> 5668.694 | Y49: 3628.287 | Z49: =[1]עקיף!H38 -> 696.4 | AA49: =[1]עקיף!P38 -> 617.9 | AB49: =[1]עקיף!Q38 -> 4721.3 | AH49: 21714.884 | AI49: 198.3 | AL49: 40.094375 | AM49: 19260
A50: 36069 | B50: =MONTH(A50) -> 10 | C50: =ROUNDUP(B50/3,0) -> 4 | D50: =YEAR(A50) -> 1998 | E50: 69.313512 | F50: 5018.9 | G50: 3886.4 | H50: 2383.5 | I50: 908.6 | L50: 14.460909 | M50: 97.26 | N50: 4.194 | O50: 273.14353 | P50: 268.81765 | Q50: 1615.6945 | R50: 1032.47 | S50: 0.17 | X50: =[1]ישיר!D39/1000 -> 5927.409 | Y50: 4398.959 | Z50: =[1]עקיף!H39 -> 908.6 | AA50: =[1]עקיף!P39 -> 645.8 | AB50: =[1]עקיף!Q39 -> 3937.9 | AH50: 21914.409 | AI50: 204.4 | AL50: 40.272728 | AM50: 21420
A51: 36100 | B51: =MONTH(A51) -> 11 | C51: =ROUNDUP(B51/3,0) -> 4 | D51: =YEAR(A51) -> 1998 | E51: 70.200523 | F51: 4918.7 | G51: 4455.4 | H51: 3021.7 | I51: 634.7 | L51: 13.002105 | M51: 89.39 | N51: 4.2263333 | O51: 290.30636 | P51: 283.59864 | Q51: 1888.721 | R51: 1144.4335 | S51: 0.17 | X51: =[1]ישיר!D40/1000 -> 4879.52 | Y51: 3637.065 | Z51: =[1]עקיף!H40 -> 634.7 | AA51: =[1]עקיף!P40 -> 686.3 | AB51: =[1]עקיף!Q40 -> 4342.7 | AH51: 22478.556 | AI51: 204.4 | AL51: 40.328702 | AM51: 19356
...

Sheet Quarterly
A1: Type | D1: SA | E1: Nominal | F1: Real | G1: SA | H1: SA | I1: SA | J1: SA | K1: SA
A2: Source | D2: CBS | E2: BOI | F2: CBS | G2: CBS | H2: CBS | I2: CBS | J2: CBS | K2: CBS
A3: Release Lag
A4: Date | B4: Quarter | C4: Year | D4: GDP | E4: Intrest_rate | F4: CPI | G4: C | H4: G | I4: I | J4: EX | K4: IM
A5: 1995Q1 | B5: =_xlfn.NUMBERVALUE(RIGHT(A5,1)) -> 1 | C5: =_xlfn.NUMBERVALUE(LEFT(A5,4)) -> 1995 | D5: 137232.58 | F5: =AVERAGEIFS(Monthly!$E$5:$E$361,Monthly!$D$5:$D$361,Quarterly!C5,Monthly!$C$5:$C$361,Quarterly!B5) -> 50.686298 | G5: 70112.724 | H5: 39908.198 | I5: 37992.38 | J5: 29244.223 | K5: 36840.081
A6: 1995Q2 | B6: =_xlfn.NUMBERVALUE(RIGHT(A6,1)) -> 2 | C6: =_xlfn.NUMBERVALUE(LEFT(A6,4)) -> 1995 | D6: 140074.89 | F6: =AVERAGEIFS(Monthly!$E$5:$E$361,Monthly!$D$5:$D$361,Quarterly!C6,Monthly!$C$5:$C$361,Quarterly!B6) -> 51.545149 | G6: 70331.653 | H6: 40199.49 | I6: 39062.304 | J6: 30179.386 | K6: 36457.797
A7: 1995Q3 | B7: =_xlfn.NUMBERVALUE(RIGHT(A7,1)) -> 3 | C7: =_xlfn.NUMBERVALUE(LEFT(A7,4)) -> 1995 | D7: 141735.09 | F7: =AVERAGEIFS(Monthly!$E$5:$E$361,Monthly!$D$5:$D$361,Quarterly!C7,Monthly!$C$5:$C$361,Quarterly!B7) -> 52.544796 | G7: 71057.324 | H7: 39524.852 | I7: 39289.253 | J7: 30462.717 | K7: 36058.63
A8: 1995Q4 | B8: =_xlfn.NUMBERVALUE(RIGHT(A8,1)) -> 4 | C8: =_xlfn.NUMBERVALUE(LEFT(A8,4)) -> 1995 | D8: 142643.51 | F8: =AVERAGEIFS(Monthly!$E$5:$E$361,Monthly!$D$5:$D$361,Quarterly!C8,Monthly!$C$5:$C$361,Quarterly!B8) -> 54.107623 | G8: 74416.6 | H8: 40078.902 | I8: 40124.547 | J8: 31595.34 | K8: 40014.707
A9: 1996Q1 | B9: =_xlfn.NUMBERVALUE(RIGHT(A9,1)) -> 1 | C9: =_xlfn.NUMBERVALUE(LEFT(A9,4)) -> 1996 | D9: 144318.53 | E9: 13.9 | F9: =AVERAGEIFS(Monthly!$E$5:$E$361,Monthly!$D$5:$D$361,Quarterly!C9,Monthly!$C$5:$C$361,Quarterly!B9) -> 55.642291 | G9: 74520.56 | H9: 40261.575 | I9: 40536.667 | J9: 31807.756 | K9: 39798.936
A10: 1996Q2 | B10: =_xlfn.NUMBERVALUE(RIGHT(A10,1)) -> 2 | C10: =_xlfn.NUMBERVALUE(LEFT(A10,4)) -> 1996 | D10: 147008.83 | E10: 15.236651 | F10: =AVERAGEIFS(Monthly!$E$5:$E$361,Monthly!$D$5:$D$361,Quarterly!C10,Monthly!$C$5:$C$361,Quarterly!B10) -> 57.895016 | G10: 75123.63 | H10: 41118.345 | I10: 42313.937 | J10: 30887.838 | K10: 39567.856
A11: 1996Q3 | B11: =_xlfn.NUMBERVALUE(RIGHT(A11,1)) -> 3 | C11: =_xlfn.NUMBERVALUE(LEFT(A11,4)) -> 1996 | D11: 149008.95 | E11: 16.336663 | F11: =AVERAGEIFS(Monthly!$E$5:$E$361,Monthly!$D$5:$D$361,Quarterly!C11,Monthly!$C$5:$C$361,Quarterly!B11) -> 58.894662 | G11: 75798.548 | H11: 41773.388 | I11: 41864.571 | J11: 32414.162 | K11: 40044.299
A12: 1996Q4 | B12: =_xlfn.NUMBERVALUE(RIGHT(A12,1)) -> 4 | C12: =_xlfn.NUMBERVALUE(LEFT(A12,4)) -> 1996 | D12: 151348.65 | E12: 15.266666 | F12: =AVERAGEIFS(Monthly!$E$5:$E$361,Monthly!$D$5:$D$361,Quarterly!C12,Monthly!$C$5:$C$361,Quarterly!B12) -> 60.006945 | G12: 76031.798 | H12: 42126.159 | I12: 42863.837 | J12: 33491.553 | K12: 40472.251
A13: 1997Q1 | B13: =_xlfn.NUMBERVALUE(RIGHT(A13,1)) -> 1 | C13: =_xlfn.NUMBERVALUE(LEFT(A13,4)) -> 1997 | D13: 153122.92 | E13: 14.243332 | F13: =AVERAGEIFS(Monthly!$E$5:$E$361,Monthly!$D$5:$D$361,Quarterly!C13,Monthly!$C$5:$C$361,Quarterly!B13) -> 61.372659 | G13: 77275.745 | H13: 42428.149 | I13: 42977.221 | J13: 34422.559 | K13: 41115.247
A14: 1997Q2 | B14: =_xlfn.NUMBERVALUE(RIGHT(A14,1)) -> 2 | C14: =_xlfn.NUMBERVALUE(LEFT(A14,4)) -> 1997 | D14: 153196.91 | E14: 13.746666 | F14: =AVERAGEIFS(Monthly!$E$5:$E$361,Monthly!$D$5:$D$361,Quarterly!C14,Monthly!$C$5:$C$361,Quarterly!B14) -> 62.893248 | G14: 78051.646 | H14: 42335.013 | I14: 41372.408 | J14: 35330.658 | K14: 41892.745
A15: 1997Q3 | B15: =_xlfn.NUMBERVALUE(RIGHT(A15,1)) -> 3 | C15: =_xlfn.NUMBERVALUE(LEFT(A15,4)) -> 1997 | D15: 153345.82 | E15: 12.993332 | F15: =AVERAGEIFS(Monthly!$E$5:$E$361,Monthly!$D$5:$D$361,Quarterly!C15,Monthly!$C$5:$C$361,Quarterly!B15) -> 64.230803 | G15: 78378.35 | H15: 42502.158 | I15: 41664.256 | J15: 36221.859 | K15: 42057.129
A16: 1997Q4 | B16: =_xlfn.NUMBERVALUE(RIGHT(A16,1)) -> 4 | C16: =_xlfn.NUMBERVALUE(LEFT(A16,4)) -> 1997 | D16: 156122.17 | E16: 13.4 | F16: =AVERAGEIFS(Monthly!$E$5:$E$361,Monthly!$D$5:$D$361,Quarterly!C16,Monthly!$C$5:$C$361,Quarterly!B16) -> 64.864382 | G16: 80277.193 | H16: 42537.018 | I16: 41173.221 | J16: 36699.206 | K16: 42598.726
A17: 1998Q1 | B17: =_xlfn.NUMBERVALUE(RIGHT(A17,1)) -> 1 | C17: =_xlfn.NUMBERVALUE(LEFT(A17,4)) -> 1998 | D17: 159174.55 | E17: 12.929999 | F17: =AVERAGEIFS(Monthly!$E$5:$E$361,Monthly!$D$5:$D$361,Quarterly!C17,Monthly!$C$5:$C$361,Quarterly!B17) -> 64.808064 | G17: 81341.023 | H17: 42945.884 | I17: 42791.342 | J17: 36321.602 | K17: 42277.636
A18: 1998Q2 | B18: =_xlfn.NUMBERVALUE(RIGHT(A18,1)) -> 2 | C18: =_xlfn.NUMBERVALUE(LEFT(A18,4)) -> 1998 | D18: 158400.94 | E18: 11.899999 | F18: =AVERAGEIFS(Monthly!$E$5:$E$361,Monthly!$D$5:$D$361,Quarterly!C18,Monthly!$C$5:$C$361,Quarterly!B18) -> 65.849949 | G18: 83355.689 | H18: 43152.955 | I18: 38905.991 | J18: 39524.165 | K18: 43416.235
A19: 1998Q3 | B19: =_xlfn.NUMBERVALUE(RIGHT(A19,1)) -> 3 | C19: =_xlfn.NUMBERVALUE(LEFT(A19,4)) -> 1998 | D19: 159913.42 | E19: 10.393326 | F19: =AVERAGEIFS(Monthly!$E$5:$E$361,Monthly!$D$5:$D$361,Quarterly!C19,Monthly!$C$5:$C$361,Quarterly!B19) -> 66.553925 | G19: 83887.655 | H19: 43425.551 | I19: 41357.722 | J19: 37999.69 | K19: 43369.894
A20: 1998Q4 | B20: =_xlfn.NUMBERVALUE(RIGHT(A20,1)) -> 4 | C20: =_xlfn.NUMBERVALUE(LEFT(A20,4)) -> 1998 | D20: 160587.88 | E20: 11.999969 | F20: =AVERAGEIFS(Monthly!$E$5:$E$361,Monthly!$D$5:$D$361,Quarterly!C20,Monthly!$C$5:$C$361,Quarterly!B20) -> 69.918932 | G20: 84014.781 | H20: 43241.044 | I20: 41149.944 | J20: 38530.162 | K20: 43673.28
... A123: 2024Q3 | B123: =_xlfn.NUMBERVALUE(RIGHT(A123,1)) -> 3 | C123: =_xlfn.NUMBERVALUE(LEFT(A123,4)) -> 2024 | D123: 404759.83 | E123: 4.5 | F123: =AVERAGEIFS(Monthly!$E$5:$E$361,Monthly!$D$5:$D$361,Quarterly!C123,Monthly!$C$5:$C$361,Quarterly!B123) -> 100.9311 | G123: 213442.08 | H123: 97422.864 | I123: 96190.374 | J123: 119728.66 | K123: 118280.44
A124: 2024Q4 | B124: =_xlfn.NUMBERVALUE(RIGHT(A124,1)) -> 4 | C124: =_xlfn.NUMBERVALUE(LEFT(A124,4)) -> 2024 | D124: 406817.06 | E124: 4.5 | F124: =AVERAGEIFS(Monthly!$E$5:$E$3581,Monthly!$D$5:$D$3581,Quarterly!C124,Monthly!$C$5:$C$3581,Quarterly!B124) -> 101.24146 | G124: 218387.61 | H124: 99658.21 | I124: 91521.572 | J124: 121331.48 | K124: 123343.27
A125: 2025Q1 | B125: =_xlfn.NUMBERVALUE(RIGHT(A125,1)) -> 1 | C125: =_xlfn.NUMBERVALUE(LEFT(A125,4)) -> 2025 | E125: 4.5 | F125: =AVERAGEIFS(Monthly!$E$5:$E$3581,Monthly!$D$5:$D$3581,Quarterly!C125,Monthly!$C$5:$C$3581,Quarterly!B125) -> 101.66667
